[I 21:50:15.113 NotebookApp] JupyterLab extension loaded from /home/zhangzy/anaconda3/lib/python3.6/site-packages/jupyterlab
[I 21:50:15.113 NotebookApp] JupyterLab application directory is /home/zhangzy/anaconda3/share/jupyter/lab
[I 21:50:15.115 NotebookApp] Serving notebooks from local directory: /home/zhangzy/ProgrammingAlpha
[I 21:50:15.115 NotebookApp] The Jupyter Notebook is running at:
[I 21:50:15.115 NotebookApp] http://(server3 or 127.0.0.1):8888/
[I 21:50:15.115 NotebookApp] Use Control-C to stop this server and shut down all kernels (twice to skip confirmation).
[I 21:50:27.462 NotebookApp] 302 GET / (192.168.3.170) 1.22ms
[W 21:50:27.465 NotebookApp] Clearing invalid/expired login cookie username-192-168-3-212-8888
[W 21:50:27.467 NotebookApp] Clearing invalid/expired login cookie username-192-168-3-212-8888
[I 21:50:27.468 NotebookApp] 302 GET /tree? (192.168.3.170) 3.57ms
[I 21:50:30.614 NotebookApp] 302 POST /login?next=%2Ftree%3F (192.168.3.170) 1.92ms
[I 21:50:35.586 NotebookApp] Creating new notebook in 
[E 21:50:35.589 NotebookApp] Error while saving file: Untitled.ipynb [Errno 13] Permission denied: '/home/zhangzy/.local/share/jupyter'
    Traceback (most recent call last):
      File "/home/zhangzy/anaconda3/lib/python3.6/site-packages/traitlets/traitlets.py", line 528, in get
        value = obj._trait_values[self.name]
    KeyError: 'notary'
    
    During handling of the above exception, another exception occurred:
    
    Traceback (most recent call last):
      File "/home/zhangzy/anaconda3/lib/python3.6/site-packages/traitlets/traitlets.py", line 528, in get
        value = obj._trait_values[self.name]
    KeyError: 'db_file'
    
    During handling of the above exception, another exception occurred:
    
    Traceback (most recent call last):
      File "/home/zhangzy/anaconda3/lib/python3.6/site-packages/traitlets/traitlets.py", line 528, in get
        value = obj._trait_values[self.name]
    KeyError: 'data_dir'
    
    During handling of the above exception, another exception occurred:
    
    Traceback (most recent call last):
      File "/home/zhangzy/anaconda3/lib/python3.6/site-packages/traitlets/traitlets.py", line 528, in get
        value = obj._trait_values[self.name]
    KeyError: 'data_dir'
    
    During handling of the above exception, another exception occurred:
    
    Traceback (most recent call last):
      File "/home/zhangzy/anaconda3/lib/python3.6/site-packages/notebook/services/contents/filemanager.py", line 470, in save
        self.check_and_sign(nb, path)
      File "/home/zhangzy/anaconda3/lib/python3.6/site-packages/notebook/services/contents/manager.py", line 486, in check_and_sign
        if self.notary.check_cells(nb):
      File "/home/zhangzy/anaconda3/lib/python3.6/site-packages/traitlets/traitlets.py", line 556, in __get__
        return self.get(obj, cls)
      File "/home/zhangzy/anaconda3/lib/python3.6/site-packages/traitlets/traitlets.py", line 535, in get
        value = self._validate(obj, dynamic_default())
      File "/home/zhangzy/anaconda3/lib/python3.6/site-packages/notebook/services/contents/manager.py", line 65, in _notary_default
        return sign.NotebookNotary(parent=self)
      File "/home/zhangzy/anaconda3/lib/python3.6/site-packages/nbformat/sign.py", line 392, in __init__
        self.store = self.store_factory()
      File "/home/zhangzy/anaconda3/lib/python3.6/site-packages/nbformat/sign.py", line 340, in factory
        return SQLiteSignatureStore(self.db_file)
      File "/home/zhangzy/anaconda3/lib/python3.6/site-packages/traitlets/traitlets.py", line 556, in __get__
        return self.get(obj, cls)
      File "/home/zhangzy/anaconda3/lib/python3.6/site-packages/traitlets/traitlets.py", line 535, in get
        value = self._validate(obj, dynamic_default())
      File "/home/zhangzy/anaconda3/lib/python3.6/site-packages/nbformat/sign.py", line 351, in _db_file_default
        if not self.data_dir:
      File "/home/zhangzy/anaconda3/lib/python3.6/site-packages/traitlets/traitlets.py", line 556, in __get__
        return self.get(obj, cls)
      File "/home/zhangzy/anaconda3/lib/python3.6/site-packages/traitlets/traitlets.py", line 535, in get
        value = self._validate(obj, dynamic_default())
      File "/home/zhangzy/anaconda3/lib/python3.6/site-packages/nbformat/sign.py", line 328, in _data_dir_default
        return app.data_dir
      File "/home/zhangzy/anaconda3/lib/python3.6/site-packages/traitlets/traitlets.py", line 556, in __get__
        return self.get(obj, cls)
      File "/home/zhangzy/anaconda3/lib/python3.6/site-packages/traitlets/traitlets.py", line 535, in get
        value = self._validate(obj, dynamic_default())
      File "/home/zhangzy/anaconda3/lib/python3.6/site-packages/jupyter_core/application.py", line 93, in _data_dir_default
        ensure_dir_exists(d, mode=0o700)
      File "/home/zhangzy/anaconda3/lib/python3.6/site-packages/jupyter_core/utils/__init__.py", line 13, in ensure_dir_exists
        os.makedirs(path, mode=mode)
      File "/home/zhangzy/anaconda3/lib/python3.6/os.py", line 220, in makedirs
        mkdir(name, mode)
    PermissionError: [Errno 13] Permission denied: '/home/zhangzy/.local/share/jupyter'
[W 21:50:35.593 NotebookApp] 500 POST /api/contents (192.168.3.170): Unexpected error while saving file: Untitled.ipynb [Errno 13] Permission denied: '/home/zhangzy/.local/share/jupyter'
[W 21:50:35.594 NotebookApp] Unexpected error while saving file: Untitled.ipynb [Errno 13] Permission denied: '/home/zhangzy/.local/share/jupyter'
[E 21:50:35.594 NotebookApp] {
      "Host": "192.168.3.212:8888",
      "User-Agent": "Mozilla/5.0 (X11; Ubuntu; Linux x86_64; rv:64.0) Gecko/20100101 Firefox/64.0",
      "Accept": "application/json, text/javascript, */*; q=0.01",
      "Accept-Language": "en-US,en;q=0.5",
      "Accept-Encoding": "gzip, deflate",
      "Referer": "http://192.168.3.212:8888/tree?",
      "Content-Type": "application/json",
      "X-Xsrftoken": "2|dcab8151|aa9a81131f27416faa18f0ecc5e44fa4|1545744286",
      "X-Requested-With": "XMLHttpRequest",
      "Content-Length": "19",
      "Connection": "keep-alive",
      "Cookie": "_xsrf=2|dcab8151|aa9a81131f27416faa18f0ecc5e44fa4|1545744286; username-192-168-3-212-8888=\"2|1:0|10:1545745830|27:username-192-168-3-212-8888|44:ZWZhOTAwOWM5Y2I0NDkwN2FhYmNmOWQ5OTNlN2JkNjA=|6d8bd040243d8d8802584d1ba2d43e815beb70d6405820c99822e1fed231e8ca\""
    }
[E 21:50:35.594 NotebookApp] 500 POST /api/contents (192.168.3.170) 9.70ms referer=http://192.168.3.212:8888/tree?
[I 21:51:27.524 NotebookApp] Creating new notebook in 
[E 21:51:27.526 NotebookApp] Error while saving file: Untitled.ipynb [Errno 13] Permission denied: '/home/zhangzy/.local/share/jupyter'
    Traceback (most recent call last):
      File "/home/zhangzy/anaconda3/lib/python3.6/site-packages/traitlets/traitlets.py", line 528, in get
        value = obj._trait_values[self.name]
    KeyError: 'notary'
    
    During handling of the above exception, another exception occurred:
    
    Traceback (most recent call last):
      File "/home/zhangzy/anaconda3/lib/python3.6/site-packages/traitlets/traitlets.py", line 528, in get
        value = obj._trait_values[self.name]
    KeyError: 'db_file'
    
    During handling of the above exception, another exception occurred:
    
    Traceback (most recent call last):
      File "/home/zhangzy/anaconda3/lib/python3.6/site-packages/traitlets/traitlets.py", line 528, in get
        value = obj._trait_values[self.name]
    KeyError: 'data_dir'
    
    During handling of the above exception, another exception occurred:
    
    Traceback (most recent call last):
      File "/home/zhangzy/anaconda3/lib/python3.6/site-packages/traitlets/traitlets.py", line 528, in get
        value = obj._trait_values[self.name]
    KeyError: 'data_dir'
    
    During handling of the above exception, another exception occurred:
    
    Traceback (most recent call last):
      File "/home/zhangzy/anaconda3/lib/python3.6/site-packages/notebook/services/contents/filemanager.py", line 470, in save
        self.check_and_sign(nb, path)
      File "/home/zhangzy/anaconda3/lib/python3.6/site-packages/notebook/services/contents/manager.py", line 486, in check_and_sign
        if self.notary.check_cells(nb):
      File "/home/zhangzy/anaconda3/lib/python3.6/site-packages/traitlets/traitlets.py", line 556, in __get__
        return self.get(obj, cls)
      File "/home/zhangzy/anaconda3/lib/python3.6/site-packages/traitlets/traitlets.py", line 535, in get
        value = self._validate(obj, dynamic_default())
      File "/home/zhangzy/anaconda3/lib/python3.6/site-packages/notebook/services/contents/manager.py", line 65, in _notary_default
        return sign.NotebookNotary(parent=self)
      File "/home/zhangzy/anaconda3/lib/python3.6/site-packages/nbformat/sign.py", line 392, in __init__
        self.store = self.store_factory()
      File "/home/zhangzy/anaconda3/lib/python3.6/site-packages/nbformat/sign.py", line 340, in factory
        return SQLiteSignatureStore(self.db_file)
      File "/home/zhangzy/anaconda3/lib/python3.6/site-packages/traitlets/traitlets.py", line 556, in __get__
        return self.get(obj, cls)
      File "/home/zhangzy/anaconda3/lib/python3.6/site-packages/traitlets/traitlets.py", line 535, in get
        value = self._validate(obj, dynamic_default())
      File "/home/zhangzy/anaconda3/lib/python3.6/site-packages/nbformat/sign.py", line 351, in _db_file_default
        if not self.data_dir:
      File "/home/zhangzy/anaconda3/lib/python3.6/site-packages/traitlets/traitlets.py", line 556, in __get__
        return self.get(obj, cls)
      File "/home/zhangzy/anaconda3/lib/python3.6/site-packages/traitlets/traitlets.py", line 535, in get
        value = self._validate(obj, dynamic_default())
      File "/home/zhangzy/anaconda3/lib/python3.6/site-packages/nbformat/sign.py", line 328, in _data_dir_default
        return app.data_dir
      File "/home/zhangzy/anaconda3/lib/python3.6/site-packages/traitlets/traitlets.py", line 556, in __get__
        return self.get(obj, cls)
      File "/home/zhangzy/anaconda3/lib/python3.6/site-packages/traitlets/traitlets.py", line 535, in get
        value = self._validate(obj, dynamic_default())
      File "/home/zhangzy/anaconda3/lib/python3.6/site-packages/jupyter_core/application.py", line 93, in _data_dir_default
        ensure_dir_exists(d, mode=0o700)
      File "/home/zhangzy/anaconda3/lib/python3.6/site-packages/jupyter_core/utils/__init__.py", line 13, in ensure_dir_exists
        os.makedirs(path, mode=mode)
      File "/home/zhangzy/anaconda3/lib/python3.6/os.py", line 220, in makedirs
        mkdir(name, mode)
    PermissionError: [Errno 13] Permission denied: '/home/zhangzy/.local/share/jupyter'
[W 21:51:27.527 NotebookApp] 500 POST /api/contents (192.168.3.170): Unexpected error while saving file: Untitled.ipynb [Errno 13] Permission denied: '/home/zhangzy/.local/share/jupyter'
[W 21:51:27.527 NotebookApp] Unexpected error while saving file: Untitled.ipynb [Errno 13] Permission denied: '/home/zhangzy/.local/share/jupyter'
[E 21:51:27.528 NotebookApp] {
      "Host": "192.168.3.212:8888",
      "User-Agent": "Mozilla/5.0 (X11; Ubuntu; Linux x86_64; rv:64.0) Gecko/20100101 Firefox/64.0",
      "Accept": "application/json, text/javascript, */*; q=0.01",
      "Accept-Language": "en-US,en;q=0.5",
      "Accept-Encoding": "gzip, deflate",
      "Referer": "http://192.168.3.212:8888/tree?",
      "Content-Type": "application/json",
      "X-Xsrftoken": "2|dcab8151|aa9a81131f27416faa18f0ecc5e44fa4|1545744286",
      "X-Requested-With": "XMLHttpRequest",
      "Content-Length": "19",
      "Connection": "keep-alive",
      "Cookie": "_xsrf=2|dcab8151|aa9a81131f27416faa18f0ecc5e44fa4|1545744286; username-192-168-3-212-8888=\"2|1:0|10:1545745830|27:username-192-168-3-212-8888|44:ZWZhOTAwOWM5Y2I0NDkwN2FhYmNmOWQ5OTNlN2JkNjA=|6d8bd040243d8d8802584d1ba2d43e815beb70d6405820c99822e1fed231e8ca\""
    }
[E 21:51:27.528 NotebookApp] 500 POST /api/contents (192.168.3.170) 5.17ms referer=http://192.168.3.212:8888/tree?
[I 21:58:19.729 NotebookApp] Creating new notebook in 
[I 21:58:19.933 NotebookApp] Writing notebook-signing key to /home/zhangzy/.local/share/jupyter/notebook_secret
[I 21:58:21.117 NotebookApp] Kernel started: 9220d935-cf18-4dca-a900-e9fff34c41e9
[I 21:58:22.377 NotebookApp] Adapting to protocol v5.1 for kernel 9220d935-cf18-4dca-a900-e9fff34c41e9
[I 22:00:21.052 NotebookApp] Saving file at /Untitled.ipynb
[I 08:55:16.821 NotebookApp] Saving file at /Untitled.ipynb
[I 11:36:21.191 NotebookApp] Saving file at /dataExplore.ipynb
[I 12:56:21.252 NotebookApp] Saving file at /dataExplore.ipynb
[I 12:58:21.257 NotebookApp] Saving file at /dataExplore.ipynb
[I 16:43:50.764 NotebookApp] Starting buffering for 9220d935-cf18-4dca-a900-e9fff34c41e9:223c9715416e4b25ae0a825f49620fc0
